Workbook
Name Slicer_Distance_category: #N/A
Name Slicer_Storage_method: #N/A
Name Slicer_Transport_Method: #N/A

Sheet Patter_Analysis
A3: Storage_method | B3: Average of Loss_rate | E3: Distance | F3: Average of Loss_rate
A4: cold storage | B4: 0.12924178 | E4: Far | F4: 0.18570973
A5: Improved storage | B5: 0.1051119 | E5: Medium distance | F5: 0.13503539
A6: No storage | B6: 0.15392166 | E6: Near | F6: 0.11556025
A7: Traditional storage | B7: 0.13697785 | E7: Grand Total | F7: 0.13670324
A8: Grand Total | B8: 0.13670324
A13: Transport_method | B13: Average of Loss_rate | E13: Days_before_sale | F13: Average of Loss_rate
A14: Bicycle | B14: 0.14683574 | E14: Long delay | F14: 0.16723511
A15: Motor cycle | B15: 0.15548592 | E15: Moderate delay | F15: 0.13281079
A16: Other | B16: 0.13575695 | E16: Quick sale | F16: 0.10695518
A17: Pick up | B17: 0.11889424 | E17: Grand Total | F17: 0.13670324
A18: Truck | B18: 0.13216727
A19: Grand Total | B19: 0.13670324
B23: Average of Loss rate | E23: Days_before_sale | F23: Count of Farmer_ID
B24: 0.13670324 | E24: Highest loss | F24: 13
D25: 150 | E25: Lowest loss | F25: 40
D26: 0.13670324 | E26: Medium loss | F26: 97
D27: 13 | E27: Grand Total | F27: 150

Sheet Dashboard

Sheet Clean_Data
A1: Farmer_ID | B1: Harvest_check | C1: Quantity_lost | D1: Loss_rate | E1: Loss_rate_range | F1: Quantity_sold | G1: Storage_method | H1: Transport_Method | I1: Distance_to_market | J1: Days_Before_Sale | K1: Days_category | L1: Distance_category | M1: Selling_price | N1: Revenue
A2: F074 | B2: 1300 | C2: 118 | D2: =(C2/B2) -> 0.090769231 | E2: =IF(D2<=10%,"Lowest loss",IF(D2<=20%,"Medium loss","Highest loss")) -> Lowest loss | F2: 1120 | G2: Improved storage | H2: Truck | I2: 7.6 | J2: 3 | K2: =IF(J2="","Missing",IF(J2<=1,"Quick sale",IF(J2<=3,"Moderate delay","Long delay"))) -> Moderate delay | L2: =IF(I2="","Missing",IF(I2<=10,"Near",IF(I2<=30,"Medium distance","Far"))) -> Near | M2: 1479 | N2: =IF(OR(F2="",M2=""),"",F2*M2) -> 1656480
A3: F019 | B3: 334 | C3: 54 | D3: =(C3/B3) -> 0.16167665 | E3: =IF(D3<=10%,"Lowest loss",IF(D3<=20%,"Medium loss","Highest loss")) -> Medium loss | F3: 259 | G3: No storage | H3: Other | I3: 33.7 | J3: 1 | K3: =IF(J3="","Missing",IF(J3<=1,"Quick sale",IF(J3<=3,"Moderate delay","Long delay"))) -> Quick sale | L3: =IF(I3="","Missing",IF(I3<=10,"Near",IF(I3<=30,"Medium distance","Far"))) -> Far | M3: 1124 | N3: =IF(OR(F3="",M3=""),"",F3*M3) -> 291116
A4: F119 | B4: 1031 | C4: 189 | D4: =(C4/B4) -> 0.18331717 | E4: =IF(D4<=10%,"Lowest loss",IF(D4<=20%,"Medium loss","Highest loss")) -> Medium loss | F4: 775 | G4: Traditional storage | H4: Motor cycle | I4: 29.4 | J4: 4 | K4: =IF(J4="","Missing",IF(J4<=1,"Quick sale",IF(J4<=3,"Moderate delay","Long delay"))) -> Long delay | L4: =IF(I4="","Missing",IF(I4<=10,"Near",IF(I4<=30,"Medium distance","Far"))) -> Medium distance | M4: 1599 | N4: =IF(OR(F4="",M4=""),"",F4*M4) -> 1239225
A5: F079 | B5: 578 | C5: 42 | D5: =(C5/B5) -> 0.07266436 | E5: =IF(D5<=10%,"Lowest loss",IF(D5<=20%,"Medium loss","Highest loss")) -> Lowest loss | F5: 534 | G5: Improved storage | H5: Pick up | I5: 16 | J5: 1 | K5: =IF(J5="","Missing",IF(J5<=1,"Quick sale",IF(J5<=3,"Moderate delay","Long delay"))) -> Quick sale | L5: =IF(I5="","Missing",IF(I5<=10,"Near",IF(I5<=30,"Medium distance","Far"))) -> Medium distance | M5: 1721 | N5: =IF(OR(F5="",M5=""),"",F5*M5) -> 919014
A6: F077 | B6: 577 | C6: 115 | D6: =(C6/B6) -> 0.19930676 | E6: =IF(D6<=10%,"Lowest loss",IF(D6<=20%,"Medium loss","Highest loss")) -> Medium loss | F6: 422 | G6: Traditional storage | H6: Motor cycle | I6: 9.5 | J6: 7 | K6: =IF(J6="","Missing",IF(J6<=1,"Quick sale",IF(J6<=3,"Moderate delay","Long delay"))) -> Long delay | L6: =IF(I6="","Missing",IF(I6<=10,"Near",IF(I6<=30,"Medium distance","Far"))) -> Near | M6: 962 | N6: =IF(OR(F6="",M6=""),"",F6*M6) -> 405964
A7: F032 | B7: 1523 | C7: 208 | D7: =(C7/B7) -> 0.13657255 | E7: =IF(D7<=10%,"Lowest loss",IF(D7<=20%,"Medium loss","Highest loss")) -> Medium loss | F7: 1267 | G7: Traditional storage | H7: Motor cycle | I7: 0 | J7: 4 | K7: =IF(J7="","Missing",IF(J7<=1,"Quick sale",IF(J7<=3,"Moderate delay","Long delay"))) -> Long delay | L7: =IF(I7="","Missing",IF(I7<=10,"Near",IF(I7<=30,"Medium distance","Far"))) -> Near | M7: 1488 | N7: =IF(OR(F7="",M7=""),"",F7*M7) -> 1885296
A8: F065 | B8: 860 | C8: 185 | D8: =(C8/B8) -> 0.21511628 | E8: =IF(D8<=10%,"Lowest loss",IF(D8<=20%,"Medium loss","Highest loss")) -> Highest loss | F8: 635 | G8: No storage | H8: OTHER | I8: 7.4 | J8: 6 | K8: =IF(J8="","Missing",IF(J8<=1,"Quick sale",IF(J8<=3,"Moderate delay","Long delay"))) -> Long delay | L8: =IF(I8="","Missing",IF(I8<=10,"Near",IF(I8<=30,"Medium distance","Far"))) -> Near | M8: 1191 | N8: =IF(OR(F8="",M8=""),"",F8*M8) -> 756285
A9: F142 | B9: 1129 | C9: 155 | D9: =(C9/B9) -> 0.13728964 | E9: =IF(D9<=10%,"Lowest loss",IF(D9<=20%,"Medium loss","Highest loss")) -> Medium loss | F9: 956 | G9: No storage | H9: Bicycle | I9: 10.7 | J9: 1 | K9: =IF(J9="","Missing",IF(J9<=1,"Quick sale",IF(J9<=3,"Moderate delay","Long delay"))) -> Quick sale | L9: =IF(I9="","Missing",IF(I9<=10,"Near",IF(I9<=30,"Medium distance","Far"))) -> Medium distance | M9: 1452 | N9: =IF(OR(F9="",M9=""),"",F9*M9) -> 1388112
A10: F069 | B10: 671 | C10: 60 | D10: =(C10/B10) -> 0.089418778 | E10: =IF(D10<=10%,"Lowest loss",IF(D10<=20%,"Medium loss","Highest loss")) -> Lowest loss | F10: 587 | G10: Traditional storage | H10: Motor cycle | I10: 14.3 | J10: 2 | K10: =IF(J10="","Missing",IF(J10<=1,"Quick sale",IF(J10<=3,"Moderate delay","Long delay"))) -> Moderate delay | L10: =IF(I10="","Missing",IF(I10<=10,"Near",IF(I10<=30,"Medium distance","Far"))) -> Medium distance | M10: 1305 | N10: =IF(OR(F10="",M10=""),"",F10*M10) -> 766035
A11: F083 | B11: 1240 | C11: 170 | D11: =(C11/B11) -> 0.13709677 | E11: =IF(D11<=10%,"Lowest loss",IF(D11<=20%,"Medium loss","Highest loss")) -> Medium loss | F11: 972 | G11: Improved storage | H11: Motor cycle | I11: 3.3 | J11: 5 | K11: =IF(J11="","Missing",IF(J11<=1,"Quick sale",IF(J11<=3,"Moderate delay","Long delay"))) -> Long delay | L11: =IF(I11="","Missing",IF(I11<=10,"Near",IF(I11<=30,"Medium distance","Far"))) -> Near | M11: 1191 | N11: =IF(OR(F11="",M11=""),"",F11*M11) -> 1157652
A12: F111 | B12: 191 | C12: 22 | D12: =(C12/B12) -> 0.11518325 | E12: =IF(D12<=10%,"Lowest loss",IF(D12<=20%,"Medium loss","Highest loss")) -> Medium loss | F12: 156 | G12: Improved storage | H12: Motor cycle | I12: 3.9 | J12: 4 | K12: =IF(J12="","Missing",IF(J12<=1,"Quick sale",IF(J12<=3,"Moderate delay","Long delay"))) -> Long delay | L12: =IF(I12="","Missing",IF(I12<=10,"Near",IF(I12<=30,"Medium distance","Far"))) -> Near | M12: 1604 | N12: =IF(OR(F12="",M12=""),"",F12*M12) -> 250224
A13: F013 | B13: 628 | C13: 121 | D13: =(C13/B13) -> 0.19267516 | E13: =IF(D13<=10%,"Lowest loss",IF(D13<=20%,"Medium loss","Highest loss")) -> Medium loss | F13: 485 | G13: Traditional storage | H13: Pick up | I13: 15.5 | J13: 6 | K13: =IF(J13="","Missing",IF(J13<=1,"Quick sale",IF(J13<=3,"Moderate delay","Long delay"))) -> Long delay | L13: =IF(I13="","Missing",IF(I13<=10,"Near",IF(I13<=30,"Medium distance","Far"))) -> Medium distance | M13: 874 | N13: =IF(OR(F13="",M13=""),"",F13*M13) -> 423890
... A151: F103 | B151: 456 | C151: 96 | D151: =(C151/B151) -> 0.21052632 | E151: =IF(D151<=10%,"Lowest loss",IF(D151<=20%,"Medium loss","Highest loss")) -> Highest loss | F151: 356 | G151: No storage | H151: Truck | I151: 26.6 | J151: 5 | K151: =IF(J151="","Missing",IF(J151<=1,"Quick sale",IF(J151<=3,"Moderate delay","Long delay"))) -> Long delay | L151: =IF(I151="","Missing",IF(I151<=10,"Near",IF(I151<=30,"Medium distance","Far"))) -> Medium distance | M151: 0 | N151: =IF(OR(F151="",M151=""),"",F151*M151) -> 0

Sheet EDA_Statistics
A1: Statistic | B1: Harvest | C1: Sold | D1: Lost | E1: Distance | F1: Days | G1: Price | H1: Loss_rate
A2: Count | B2: =COUNT(Raw_Data!B2:B151) -> 139 | C2: =COUNT(Raw_Data!E2:E151) -> 147 | D2: =COUNT(Raw_Data!C2:C151) -> 136 | E2: =COUNT(Raw_Data!H2:H151) -> 137 | F2: =COUNT(Raw_Data!I2:I151) -> 147 | G2: =COUNT(Raw_Data!J2:J151) -> 138 | H2: =COUNT(Clean_Data!D2:D151) -> 150
A3: Mean | B3: =AVERAGE(Raw_Data!B2:B151) -> 610.2518 | C3: =AVERAGE(Raw_Data!E2:E151) -> 490.72109 | D3: =AVERAGE(Raw_Data!C2:C151) -> 84.198529 | E3: =AVERAGE(Raw_Data!H2:H151) -> 17.840876 | F3: =AVERAGE(Raw_Data!I2:I151) -> 2.8707483 | G3: =AVERAGE(Raw_Data!J2:J151) -> 1182.029
A4: Minimum | B4: =MIN(Raw_Data!B2:B151) -> 130 | C4: =MIN(Raw_Data!E2:E151) -> 117 | D4: =MIN(Raw_Data!C2:C151) -> 5 | E4: =MIN(Raw_Data!H2:H151) -> 1.5 | F4: =MIN(Raw_Data!I2:I151) -> 0 | G4: =MIN(Raw_Data!J2:J151) -> 615 | H4: =MIN(Clean_Data!D2:D151) -> 0.020491803
A5: Maximum | B5: =MAX(Raw_Data!B2:B151) -> 2132 | C5: =MAX(Raw_Data!E2:E151) -> 1588 | D5: =MAX(Raw_Data!C2:C151) -> 486 | E5: =MAX(Raw_Data!H2:H151) -> 56 | F5: =MAX(Raw_Data!I2:I151) -> 8 | G5: =MAX(Raw_Data!J2:J151) -> 1964 | H5: =MAX(Clean_Data!D3:D152) -> 0.28685259
A6: Range | B6: =MAX(Raw_Data!B2:B151)-MIN(Raw_Data!B2:B151) -> 2002 | C6: =MAX(Raw_Data!E2:E151)-MIN(Raw_Data!E2:E151) -> 1471 | D6: =MAX(Raw_Data!C2:C151)-MIN(Raw_Data!C2:C151) -> 481 | E6: =MAX(Raw_Data!H2:H151)-MIN(Raw_Data!H2:H151) -> 54.5 | F6: =MAX(Raw_Data!I2:I151)-MIN(Raw_Data!I2:I151) -> 8 | G6: =MAX(Raw_Data!J2:J151)-MIN(Raw_Data!J2:J151) -> 1349
A7: Standard Deviation | B7: =_xlfn.STDEV.S(Raw_Data!B2:B151) -> 342.0539 | C7: =_xlfn.STDEV.S(Raw_Data!E2:E151) -> 266.80304 | D7: =_xlfn.STDEV.S(Raw_Data!C2:C151) -> 65.175867 | E7: =_xlfn.STDEV.S(Raw_Data!H2:H151) -> 12.297606 | F7: =_xlfn.STDEV.S(Raw_Data!I2:I151) -> 1.7052381 | G7: =_xlfn.STDEV.S(Raw_Data!J2:J151) -> 264.6869
A8: Median | B8: =MEDIAN(Raw_Data!B2:B151) -> 529 | C8: =MEDIAN(Raw_Data!E2:E151) -> 427 | D8: =MEDIAN(Raw_Data!C2:C151) -> 72.5 | E8: =MEDIAN(Raw_Data!H2:H151) -> 14.3 | F8: =MEDIAN(Raw_Data!I2:I151) -> 3 | G8: =MEDIAN(Raw_Data!J2:J151) -> 1191.5
A9: Q1 | B9: =_xlfn.QUARTILE.INC(Raw_Data!B2:B151,1) -> 376.5 | C9: =_xlfn.QUARTILE.INC(Raw_Data!E2:E151,1) -> 299 | D9: =_xlfn.QUARTILE.INC(Raw_Data!C2:C151,1) -> 47 | E9: =_xlfn.QUARTILE.INC(Raw_Data!H2:H151,1) -> 8.8 | F9: =_xlfn.QUARTILE.INC(Raw_Data!I2:I151,1) -> 2 | G9: =_xlfn.QUARTILE.INC(Raw_Data!J2:J151,1) -> 976
A10: Q3 | B10: =_xlfn.QUARTILE.INC(Raw_Data!B2:B151,3) -> 737 | C10: =_xlfn.QUARTILE.INC(Raw_Data!E2:E151,3) -> 593.5 | D10: =_xlfn.QUARTILE.INC(Raw_Data!C2:C151,3) -> 103.5 | E10: =_xlfn.QUARTILE.INC(Raw_Data!H2:H151,3) -> 24.2 | F10: =_xlfn.QUARTILE.INC(Raw_Data!I2:I151,3) -> 4 | G10: =_xlfn.QUARTILE.INC(Raw_Data!J2:J151,3) -> 1349.5
A11: IQR | B11: =B10-B9 -> 360.5 | C11: =C10-C9 -> 294.5 | D11: =D10-D9 -> 56.5 | E11: =E10-E9 -> 15.4 | F11: =F10-F9 -> 2 | G11: =G10-G9 -> 373.5
A12: Lower bound | B12: =B9-(1.5*B11) -> -164.25 | C12: =C9-(1.5*C11) -> -142.75 | D12: =D9-(1.5*D11) -> -37.75 | E12: =E9-(1.5*E11) -> -14.3 | F12: =F9-(1.5*F11) -> -1 | G12: =G9-(1.5*G11) -> 415.75
A13: Upper bound | B13: =B10+(1.5*B11) -> 1277.75 | C13: =C10+(1.5*C11) -> 1035.25 | D13: =D10+(1.5*D11) -> 188.25 | E13: =E10+(1.5*E11) -> 47.3 | F13: =F10+(1.5*F11) -> 7 | G13: =G10+(1.5*G11) -> 1909.75

Sheet Raw_Data
A1: Farmer_ID | B1: Harvest_kg | C1: Quantity_Lost_kg | D1: farmer-distribution | E1: Quantity_Sold_kg | F1: Storage_Method | G1: Transport_Method | H1: Distance_to_Market_km | I1: Days_Before_Sale | J1: Selling_Price_TZS_per_kg
A2: F074 | B2: 1300 | C2: 118 | D2: =IF(C2="","Missing",IF(C2<50,"Low",IF(C2>=100,"Medium","High"))) -> Medium | E2: 1120 | F2: improved | G2: Truck | H2: 7.6 | I2: 3 | J2: 1479
A3: F019 | B3: 334 | C3: 54 | D3: =IF(C3="","Missing",IF(C3<50,"Low",IF(C3>=100,"Medium","High"))) -> High | E3: 259 | F3: NONE | G3: Other | H3: 33.7 | I3: 1 | J3: 1124
A4: F119 | B4: 1031 | C4: 189 | D4: =IF(C4="","Missing",IF(C4<50,"Low",IF(C4>=100,"Medium","High"))) -> Medium | E4: 775 | F4: Traditional | G4: MOTORCYCLE | H4: 29.4 | I4: 4 | J4: 1599
A5: F079 | B5: 578 | C5: 42 | D5: =IF(C5="","Missing",IF(C5<50,"Low",IF(C5>=100,"Medium","High"))) -> Low | E5: 534 | F5: Improved | G5: Pick up | H5: 16 | I5: 1 | J5: 1721
A6: F077 | B6: 577 | C6: 115 | D6: =IF(C6="","Missing",IF(C6<50,"Low",IF(C6>=100,"Medium","High"))) -> Medium | E6: 422 | F6: Traditional | G6: Motorcycle | H6: 9.5 | I6: 7 | J6: 962
A7: F032 | B7: 1523 | C7: 208 | D7: =IF(C7="","Missing",IF(C7<50,"Low",IF(C7>=100,"Medium","High"))) -> Medium | E7: 1267 | F7: Traditional | G7: Motorcycle | H7: -5 km | I7: 4 | J7: 1488
A8: F065 | B8: 860 | C8: 185 | D8: =IF(C8="","Missing",IF(C8<50,"Low",IF(C8>=100,"Medium","High"))) -> Medium | E8: 635 | F8: None | G8: OTHER | H8: 7.4 | I8: 6
A9: F142 | B9: 1129 | C9: 155 | D9: =IF(C9="","Missing",IF(C9<50,"Low",IF(C9>=100,"Medium","High"))) -> Medium | E9: 956 | F9: None | G9: Bicycle | H9: 10.7 | I9: 1 | J9: 1452
A10: F069 | B10: 671 | C10: 60 kg | D10: =IF(C10="","Missing",IF(C10<50,"Low",IF(C10>=100,"Medium","High"))) -> Medium | E10: 587 | F10: Traditional | G10: Motor cycle | I10: 2 | J10: TZS 1,305
A11: F083 | B11: 1240 | C11: 170 | D11: =IF(C11="","Missing",IF(C11<50,"Low",IF(C11>=100,"Medium","High"))) -> Medium | E11: 972 | F11: Improved | G11: Motorcycle | H11: 3.3 | I11: 5
A12: F111 | B12: 191 kg | C12: 22 | D12: =IF(C12="","Missing",IF(C12<50,"Low",IF(C12>=100,"Medium","High"))) -> Low | E12: 156 | F12: Improved | G12: Motorcycle | H12: 3.9 | I12: 4 | J12: 1604
A13: F013 | B13: 628 | C13: 121 | D13: =IF(C13="","Missing",IF(C13<50,"Low",IF(C13>=100,"Medium","High"))) -> Medium | E13: 485 | F13: Traditional | G13: Pickup | H13: 15.5 | I13: 6 | J13: 874
A14: F037 | B14: 617 | C14: 100 | D14: =IF(C14="","Missing",IF(C14<50,"Low",IF(C14>=100,"Medium","High"))) -> Medium | E14: 506 | F14: No storage | G14: truck | H14: 6.8 | I14: 4 | J14: 1266
A15: F010 | B15: 741 | C15: 92 | D15: =IF(C15="","Missing",IF(C15<50,"Low",IF(C15>=100,"Medium","High"))) -> High | E15: 620 | F15: Traditional | G15: Pickup | H15: 13.7 | I15: 1 | J15: 1408
A16: F020 | B16: 253 | C16: 49 | D16: =IF(C16="","Missing",IF(C16<50,"Low",IF(C16>=100,"Medium","High"))) -> Low | E16: 190 | F16: Improved | G16: Bicycle | H16: 39.1 | I16: 5 | J16: TZS 771
A17: F057 | B17: 347 | C17: 49 | D17: =IF(C17="","Missing",IF(C17<50,"Low",IF(C17>=100,"Medium","High"))) -> Low | E17: 285 | F17: None | G17: Pickup | H17: 6.7 | I17: 6 | J17: 931
A18: F105 | B18: 503 | C18: 28 | D18: =IF(C18="","Missing",IF(C18<50,"Low",IF(C18>=100,"Medium","High"))) -> Low | E18: 447 | F18: Traditional | G18: Pickup | H18: 1.9 | I18: 1 | J18: 1132
A19: F070 | B19: 386 | C19: 60 kg | D19: =IF(C19="","Missing",IF(C19<50,"Low",IF(C19>=100,"Medium","High"))) -> Medium | E19: 326 | F19: Traditional | G19: Pickup | H19: 22 | I19: 3 | J19: 956
A20: F056 | B20: 918 | C20: 87 | D20: =IF(C20="","Missing",IF(C20<50,"Low",IF(C20>=100,"Medium","High"))) -> High | E20: 773 | F20: None | G20: Truck | H20: 13.6 | I20: 2 | J20: TZS 1,166
A21: F133 | B21: 307 | D21: =IF(C21="","Missing",IF(C21<50,"Low",IF(C21>=100,"Medium","High"))) -> Missing | E21: 264 | F21: Traditional | G21: truck | H21: 7.9 | I21: 2 | J21: 1350
A22: F030 | B22: 468 | C22: 75 | D22: =IF(C22="","Missing",IF(C22<50,"Low",IF(C22>=100,"Medium","High"))) -> High | E22: 377 | F22: Traditional | G22: Motorcycle | H22: 40.7 | I22: 2 | J22: 1410
A23: F128 | B23: 403 kg | C23: 77 | D23: =IF(C23="","Missing",IF(C23<50,"Low",IF(C23>=100,"Medium","High"))) -> High | E23: 298 | F23: Traditional | G23: Other | H23: 38 | I23: 3 | J23: 1576
A24: F027 | B24: 292 | C24: 36 | D24: =IF(C24="","Missing",IF(C24<50,"Low",IF(C24>=100,"Medium","High"))) -> Low | E24: 252 | F24: None | G24: Motorcycle | H24: 2.8 | I24: 1 | J24: 1283
A25: F129 | B25: 581 kg | C25: 60 | D25: =IF(C25="","Missing",IF(C25<50,"Low",IF(C25>=100,"Medium","High"))) -> High | E25: 511 | F25: Traditional | G25: Motorcycle | H25: 18.2 | I25: 3 | J25: 726
A26: F132 | B26: 571 | C26: 112 | D26: =IF(C26="","Missing",IF(C26<50,"Low",IF(C26>=100,"Medium","High"))) -> Medium | E26: 451 | F26: None | G26: Pick-up | H26: 24.4 | I26: 4 | J26: 1377
A27: F146 | B27: 845 | C27: 101 | D27: =IF(C27="","Missing",IF(C27<50,"Low",IF(C27>=100,"Medium","High"))) -> Medium | E27: 727 | F27: Traditional | G27: Motorcycle | H27: 4.8 | I27: 4 | J27: 1594
A28: F109 | B28: 634 | C28: 102 | D28: =IF(C28="","Missing",IF(C28<50,"Low",IF(C28>=100,"Medium","High"))) -> Medium | E28: 505 | G28: Motorcycle | H28: 26 | I28: 3 | J28: 773
A29: F144 | B29: 609 kg | C29: 76 | D29: =IF(C29="","Missing",IF(C29<50,"Low",IF(C29>=100,"Medium","High"))) -> High | E29: 529 | F29: Traditional storage | G29: Truck | H29: 3.2 | I29: 4 | J29: 703
A30: F046 | B30: 370 | C30: 60 | D30: =IF(C30="","Missing",IF(C30<50,"Low",IF(C30>=100,"Medium","High"))) -> High | E30: 284 | F30: Traditional | G30: truck | H30: 8.5 | I30: 4 | J30: 1516
A31: F031 | B31: 395 | C31: 34 | D31: =IF(C31="","Missing",IF(C31<50,"Low",IF(C31>=100,"Medium","High"))) -> Low | E31: 341 | F31: Improved | G31: Truck | H31: 4.4 | I31: 2 | J31: 876
A32: F023 | B32: 571 | C32: 103 | D32: =IF(C32="","Missing",IF(C32<50,"Low",IF(C32>=100,"Medium","High"))) -> Medium | E32: 437 | F32: Traditional | G32: Motorcycle | H32: 43.5 | I32: 3 | J32: TZS 1,476
A33: F016 | B33: 404 | C33: 36 | D33: =IF(C33="","Missing",IF(C33<50,"Low",IF(C33>=100,"Medium","High"))) -> Low | E33: 354 | F33: None | G33: Pick-up | H33: 16.3 | I33: 1 | J33: 1304
A34: F066 | B34: 1160 | C34: 115 | D34: =IF(C34="","Missing",IF(C34<50,"Low",IF(C34>=100,"Medium","High"))) -> Medium | E34: 1020 | F34: Traditional | G34: Pickup | H34: 6.2 | I34: 5 | J34: 654
A35: F012 | B35: 426 | C35: 72 | D35: =IF(C35="","Missing",IF(C35<50,"Low",IF(C35>=100,"Medium","High"))) -> High | E35: 331 | F35: None | G35: Pickup | H35: 15 | I35: 2 | J35: 1339
A36: F043 | B36: 516 | C36: 26 | D36: =IF(C36="","Missing",IF(C36<50,"Low",IF(C36>=100,"Medium","High"))) -> Low | E36: 470 | F36: Improved | G36: Other | H36: 6.2 | I36: 1 | J36: 1335
A37: F147 | B37: 279 | C37: 36 | D37: =IF(C37="","Missing",IF(C37<50,"Low",IF(C37>=100,"Medium","High"))) -> Low | E37: 233 | F37: Traditional | G37: Pickup | H37: 12.3 | I37: 3 | J37: 1401
A38: F052 | B38: 445 | C38: 49 | D38: =IF(C38="","Missing",IF(C38<50,"Low",IF(C38>=100,"Medium","High"))) -> Low | E38: 391 | F38: Improved | G38: Truck | H38: 3.7 | I38: 5 | J38: TZS 1,115
A39: F028 | B39: 676 | C39: 105 | D39: =IF(C39="","Missing",IF(C39<50,"Low",IF(C39>=100,"Medium","High"))) -> Medium | E39: 548 | F39: None | G39: Pickup | H39: 12.2 | I39: 6 | J39: 1297
A40: F005 | B40: 484 | C40: 76 | D40: =IF(C40="","Missing",IF(C40<50,"Low",IF(C40>=100,"Medium","High"))) -> High | E40: 403 | F40: None | G40: Truck | H40: 4.7 | I40: 2 | J40: TZS 1,720
...

Sheet Data_profiling
A1: Metrics | B1: Formula | C1: Result | E1: Variable | F1: blank | G1: missmatch | H1: text/other
A2: Total records | B2: =COUNTA(Raw_Data!A2:A151) -> 150 | C2: 150 | E2: Harvest | F2: =COUNTBLANK(Raw_Data!B2:B151) -> 3 | G2: =(B2-B4) -> 11 | H2: 8
A3: Missing ID | B3: =COUNT(Raw_Data!A2:A151) -> 0 | E3: Lost values | F3: =COUNTBLANK(Raw_Data!C2:C151) -> 5 | G3: =B2-B5 -> 14 | H3: 9
A4: Total harvest filled | B4: =COUNT(Raw_Data!B2:B151) -> 139 | E4: Distance values | F4: =COUNTBLANK(Raw_Data!H2:H151) -> 4 | G4: =B2-B6 -> 13 | H4: 9
A5: Total lost values filled | B5: =COUNT(Raw_Data!C2:C151) -> 136 | E5: Sales | F5: =COUNTBLANK(Raw_Data!E2:E151) -> 1 | G5: =B2-B7 -> 3 | H5: 2
A6: Distance values filled | B6: =COUNT(Raw_Data!H2:H151) -> 137 | E6: Days | F6: =COUNTBLANK(Raw_Data!I2:I151) -> 2 | G6: =B2-B8 -> 3 | H6: 1
A7: Total sold values filled | B7: =COUNT(Raw_Data!E2:E151) -> 147 | E7: Price | F7: =COUNTBLANK(Raw_Data!J2:J151) -> 3 | G7: =B2-B9 -> 12 | H7: 9
A8: Days filled | B8: =COUNT(Raw_Data!I2:I151) -> 147
A9: Price filled | B9: =COUNT(Raw_Data!J2:J152) -> 138

Sheet Read_Me
A1: Item | B1: Details
A2: Dataset purpose | B2: Practice dataset for Excel data cleaning and post-harvest-loss analysis
A3: Rows | B3: 150 simulated farmer records
A4: Status | B4: Intentionally messy
A5: Important note | B5: Synthetic data only; not real survey observations
A6: Main outcome | B6: Post-harvest loss quantity / loss percentage
A7: Suggested first task | B7: Profile missing values, inconsistent labels, text-formatted numbers and suspicious records
